{
 "cells": [
  {
   "cell_type": "code",
   "execution_count": 1,
   "id": "e5d71d3b",
   "metadata": {},
   "outputs": [
    {
     "name": "stdout",
     "output_type": "stream",
     "text": [
      "WARNING:tensorflow:From C:\\Users\\alire\\AppData\\Roaming\\Python\\Python311\\site-packages\\keras\\src\\losses.py:2976: The name tf.losses.sparse_softmax_cross_entropy is deprecated. Please use tf.compat.v1.losses.sparse_softmax_cross_entropy instead.\n",
      "\n"
     ]
    }
   ],
   "source": [
    "import tensorflow as tf\n",
    "from tensorflow.keras import models , layers\n",
    "import matplotlib.pyplot as plt\n",
    "import numpy as np"
   ]
  },
  {
   "cell_type": "code",
   "execution_count": 2,
   "id": "ebca7c4e",
   "metadata": {
    "scrolled": true
   },
   "outputs": [
    {
     "name": "stdout",
     "output_type": "stream",
     "text": [
      "Found 4766 files belonging to 4 classes.\n"
     ]
    }
   ],
   "source": [
    "dataset = tf.keras.preprocessing.image_dataset_from_directory(\n",
    "    \"humanpose\",\n",
    "    shuffle = True ,\n",
    "    image_size = (512 , 512),\n",
    "    batch_size = 32\n",
    "    \n",
    ")"
   ]
  },
  {
   "cell_type": "code",
   "execution_count": 3,
   "id": "503e4b40",
   "metadata": {},
   "outputs": [
    {
     "data": {
      "text/plain": [
       "['bending', 'lie down', 'sitting', 'standing']"
      ]
     },
     "execution_count": 3,
     "metadata": {},
     "output_type": "execute_result"
    }
   ],
   "source": [
    "class_names = dataset.class_names\n",
    "class_names"
   ]
  },
  {
   "cell_type": "code",
   "execution_count": 4,
   "id": "4af05f12",
   "metadata": {},
   "outputs": [],
   "source": [
    "def dataset_partition (ds , train_split=0.8 , valid_split=0.1 , test_split=0.1 , shuffle=True , shuffle_size=10000 ):\n",
    "    ds_size = len(ds)\n",
    "    \n",
    "    if shuffle:\n",
    "        ds=ds.shuffle(shuffle_size , seed=12)\n",
    "    \n",
    "    \n",
    "    train_size = int(train_split * ds_size)\n",
    "    val_size = int(valid_split * ds_size)\n",
    "    \n",
    "    train_ds = ds.take(train_size)\n",
    "    val_ds = ds.skip(train_size).take(val_size)\n",
    "    test_ds = ds.skip(train_size).skip(val_size)\n",
    "\n",
    "    \n",
    "    \n",
    "    return train_ds , val_ds , test_ds\n",
    "    \n",
    "    \n"
   ]
  },
  {
   "cell_type": "code",
   "execution_count": 5,
   "id": "e9477845",
   "metadata": {},
   "outputs": [],
   "source": [
    "train_ds , val_ds , test_ds = dataset_partition(dataset)\n"
   ]
  },
  {
   "cell_type": "code",
   "execution_count": 6,
   "id": "3e7c56b1",
   "metadata": {},
   "outputs": [],
   "source": [
    "train_ds = train_ds.cache().shuffle(100).prefetch(buffer_size=tf.data.AUTOTUNE)\n",
    "val_ds = val_ds.cache().shuffle(100).prefetch(buffer_size=tf.data.AUTOTUNE)\n",
    "test_ds = test_ds.cache().shuffle(100).prefetch(buffer_size=tf.data.AUTOTUNE)"
   ]
  },
  {
   "cell_type": "code",
   "execution_count": 7,
   "id": "06a5c2d8",
   "metadata": {},
   "outputs": [
    {
     "name": "stdout",
     "output_type": "stream",
     "text": [
      "WARNING:tensorflow:From C:\\Users\\alire\\AppData\\Roaming\\Python\\Python311\\site-packages\\keras\\src\\backend.py:873: The name tf.get_default_graph is deprecated. Please use tf.compat.v1.get_default_graph instead.\n",
      "\n"
     ]
    }
   ],
   "source": [
    "resize_and_rescale = tf.keras.Sequential([\n",
    "    layers.experimental.preprocessing.Resizing(256 , 256) ,\n",
    "    layers.experimental.preprocessing.Rescaling(1.0/255) \n",
    "])"
   ]
  },
  {
   "cell_type": "code",
   "execution_count": 9,
   "id": "60e0d979",
   "metadata": {},
   "outputs": [
    {
     "name": "stdout",
     "output_type": "stream",
     "text": [
      "WARNING:tensorflow:From C:\\Users\\alire\\AppData\\Roaming\\Python\\Python311\\site-packages\\keras\\src\\layers\\pooling\\max_pooling2d.py:161: The name tf.nn.max_pool is deprecated. Please use tf.nn.max_pool2d instead.\n",
      "\n"
     ]
    }
   ],
   "source": [
    "model = models.Sequential([\n",
    "    resize_and_rescale ,\n",
    "    layers.Conv2D(32 , (3,3) , activation='relu' , input_shape=(32,256,256,3)) ,\n",
    "    layers.MaxPooling2D((2,2)) ,\n",
    "    layers.Conv2D(64 , kernel_size= (3,3) , activation='relu') ,\n",
    "    layers.MaxPooling2D((2,2)) ,\n",
    "    layers.Conv2D(64 , kernel_size= (3,3) , activation='relu') ,\n",
    "    layers.MaxPooling2D((2,2)) ,\n",
    "    layers.Conv2D(64 , (3,3) , activation='relu') ,\n",
    "    layers.MaxPooling2D((2,2)),\n",
    "    layers.Conv2D(64 , (3,3) , activation='relu') ,\n",
    "    layers.MaxPooling2D((2,2)),\n",
    "    layers.Conv2D(64 , (3,3) , activation='relu') ,\n",
    "    layers.MaxPooling2D((2,2)),\n",
    "    layers.Flatten(),\n",
    "    layers.Dense(64 , activation='relu'),\n",
    "    layers.Dense(2 , activation='softmax'),\n",
    "\n",
    "])\n",
    "\n",
    "model.build(input_shape=(32,256,256,3))"
   ]
  },
  {
   "cell_type": "code",
   "execution_count": 10,
   "id": "ef102fa2",
   "metadata": {},
   "outputs": [
    {
     "name": "stdout",
     "output_type": "stream",
     "text": [
      "WARNING:tensorflow:From C:\\Users\\alire\\AppData\\Roaming\\Python\\Python311\\site-packages\\keras\\src\\optimizers\\__init__.py:309: The name tf.train.Optimizer is deprecated. Please use tf.compat.v1.train.Optimizer instead.\n",
      "\n"
     ]
    }
   ],
   "source": [
    "model.compile(\n",
    "    optimizer='adam' ,\n",
    "    loss=tf.keras.losses.SparseCategoricalCrossentropy(from_logits=False),\n",
    "    metrics=['accuracy']\n",
    ")"
   ]
  },
  {
   "cell_type": "code",
   "execution_count": 11,
   "id": "bc5da882",
   "metadata": {},
   "outputs": [
    {
     "name": "stdout",
     "output_type": "stream",
     "text": [
      "Epoch 1/50\n",
      "WARNING:tensorflow:From C:\\Users\\alire\\AppData\\Roaming\\Python\\Python311\\site-packages\\keras\\src\\utils\\tf_utils.py:492: The name tf.ragged.RaggedTensorValue is deprecated. Please use tf.compat.v1.ragged.RaggedTensorValue instead.\n",
      "\n",
      "WARNING:tensorflow:From C:\\Users\\alire\\AppData\\Roaming\\Python\\Python311\\site-packages\\keras\\src\\engine\\base_layer_utils.py:384: The name tf.executing_eagerly_outside_functions is deprecated. Please use tf.compat.v1.executing_eagerly_outside_functions instead.\n",
      "\n"
     ]
    },
    {
     "ename": "InvalidArgumentError",
     "evalue": "Graph execution error:\n\nDetected at node sparse_categorical_crossentropy/SparseSoftmaxCrossEntropyWithLogits/SparseSoftmaxCrossEntropyWithLogits defined at (most recent call last):\n  File \"<frozen runpy>\", line 198, in _run_module_as_main\n\n  File \"<frozen runpy>\", line 88, in _run_code\n\n  File \"C:\\ProgramData\\anaconda3\\Lib\\site-packages\\ipykernel_launcher.py\", line 17, in <module>\n\n  File \"C:\\ProgramData\\anaconda3\\Lib\\site-packages\\traitlets\\config\\application.py\", line 992, in launch_instance\n\n  File \"C:\\ProgramData\\anaconda3\\Lib\\site-packages\\ipykernel\\kernelapp.py\", line 736, in start\n\n  File \"C:\\ProgramData\\anaconda3\\Lib\\site-packages\\tornado\\platform\\asyncio.py\", line 195, in start\n\n  File \"C:\\ProgramData\\anaconda3\\Lib\\asyncio\\base_events.py\", line 607, in run_forever\n\n  File \"C:\\ProgramData\\anaconda3\\Lib\\asyncio\\base_events.py\", line 1922, in _run_once\n\n  File \"C:\\ProgramData\\anaconda3\\Lib\\asyncio\\events.py\", line 80, in _run\n\n  File \"C:\\ProgramData\\anaconda3\\Lib\\site-packages\\ipykernel\\kernelbase.py\", line 516, in dispatch_queue\n\n  File \"C:\\ProgramData\\anaconda3\\Lib\\site-packages\\ipykernel\\kernelbase.py\", line 505, in process_one\n\n  File \"C:\\ProgramData\\anaconda3\\Lib\\site-packages\\ipykernel\\kernelbase.py\", line 412, in dispatch_shell\n\n  File \"C:\\ProgramData\\anaconda3\\Lib\\site-packages\\ipykernel\\kernelbase.py\", line 740, in execute_request\n\n  File \"C:\\ProgramData\\anaconda3\\Lib\\site-packages\\ipykernel\\ipkernel.py\", line 422, in do_execute\n\n  File \"C:\\ProgramData\\anaconda3\\Lib\\site-packages\\ipykernel\\zmqshell.py\", line 546, in run_cell\n\n  File \"C:\\ProgramData\\anaconda3\\Lib\\site-packages\\IPython\\core\\interactiveshell.py\", line 3024, in run_cell\n\n  File \"C:\\ProgramData\\anaconda3\\Lib\\site-packages\\IPython\\core\\interactiveshell.py\", line 3079, in _run_cell\n\n  File \"C:\\ProgramData\\anaconda3\\Lib\\site-packages\\IPython\\core\\async_helpers.py\", line 129, in _pseudo_sync_runner\n\n  File \"C:\\ProgramData\\anaconda3\\Lib\\site-packages\\IPython\\core\\interactiveshell.py\", line 3284, in run_cell_async\n\n  File \"C:\\ProgramData\\anaconda3\\Lib\\site-packages\\IPython\\core\\interactiveshell.py\", line 3466, in run_ast_nodes\n\n  File \"C:\\ProgramData\\anaconda3\\Lib\\site-packages\\IPython\\core\\interactiveshell.py\", line 3526, in run_code\n\n  File \"C:\\Users\\alire\\AppData\\Local\\Temp\\ipykernel_22080\\2147496388.py\", line 1, in <module>\n\n  File \"C:\\Users\\alire\\AppData\\Roaming\\Python\\Python311\\site-packages\\keras\\src\\utils\\traceback_utils.py\", line 65, in error_handler\n\n  File \"C:\\Users\\alire\\AppData\\Roaming\\Python\\Python311\\site-packages\\keras\\src\\engine\\training.py\", line 1807, in fit\n\n  File \"C:\\Users\\alire\\AppData\\Roaming\\Python\\Python311\\site-packages\\keras\\src\\engine\\training.py\", line 1401, in train_function\n\n  File \"C:\\Users\\alire\\AppData\\Roaming\\Python\\Python311\\site-packages\\keras\\src\\engine\\training.py\", line 1384, in step_function\n\n  File \"C:\\Users\\alire\\AppData\\Roaming\\Python\\Python311\\site-packages\\keras\\src\\engine\\training.py\", line 1373, in run_step\n\n  File \"C:\\Users\\alire\\AppData\\Roaming\\Python\\Python311\\site-packages\\keras\\src\\engine\\training.py\", line 1151, in train_step\n\n  File \"C:\\Users\\alire\\AppData\\Roaming\\Python\\Python311\\site-packages\\keras\\src\\engine\\training.py\", line 1209, in compute_loss\n\n  File \"C:\\Users\\alire\\AppData\\Roaming\\Python\\Python311\\site-packages\\keras\\src\\engine\\compile_utils.py\", line 277, in __call__\n\n  File \"C:\\Users\\alire\\AppData\\Roaming\\Python\\Python311\\site-packages\\keras\\src\\losses.py\", line 143, in __call__\n\n  File \"C:\\Users\\alire\\AppData\\Roaming\\Python\\Python311\\site-packages\\keras\\src\\losses.py\", line 270, in call\n\n  File \"C:\\Users\\alire\\AppData\\Roaming\\Python\\Python311\\site-packages\\keras\\src\\losses.py\", line 2454, in sparse_categorical_crossentropy\n\n  File \"C:\\Users\\alire\\AppData\\Roaming\\Python\\Python311\\site-packages\\keras\\src\\backend.py\", line 5775, in sparse_categorical_crossentropy\n\nReceived a label value of 3 which is outside the valid range of [0, 2).  Label values: 0 2 3 3 0 0 1 2 1 0 2 2 3 1 1 0 0 2 2 0 0 3 1 2 2 3 1 3 1 2 1 1\n\t [[{{node sparse_categorical_crossentropy/SparseSoftmaxCrossEntropyWithLogits/SparseSoftmaxCrossEntropyWithLogits}}]] [Op:__inference_train_function_3717]",
     "output_type": "error",
     "traceback": [
      "\u001b[1;31m---------------------------------------------------------------------------\u001b[0m",
      "\u001b[1;31mInvalidArgumentError\u001b[0m                      Traceback (most recent call last)",
      "Cell \u001b[1;32mIn[11], line 1\u001b[0m\n\u001b[1;32m----> 1\u001b[0m model\u001b[38;5;241m.\u001b[39mfit(\n\u001b[0;32m      2\u001b[0m     train_ds , \n\u001b[0;32m      3\u001b[0m     epochs\u001b[38;5;241m=\u001b[39m\u001b[38;5;241m50\u001b[39m , \n\u001b[0;32m      4\u001b[0m     batch_size\u001b[38;5;241m=\u001b[39m\u001b[38;5;241m32\u001b[39m , \n\u001b[0;32m      5\u001b[0m     verbose\u001b[38;5;241m=\u001b[39m\u001b[38;5;241m1\u001b[39m , \n\u001b[0;32m      6\u001b[0m     validation_data\u001b[38;5;241m=\u001b[39mval_ds\n\u001b[0;32m      7\u001b[0m \n\u001b[0;32m      8\u001b[0m \n\u001b[0;32m      9\u001b[0m \n\u001b[0;32m     10\u001b[0m )\n",
      "File \u001b[1;32m~\\AppData\\Roaming\\Python\\Python311\\site-packages\\keras\\src\\utils\\traceback_utils.py:70\u001b[0m, in \u001b[0;36mfilter_traceback.<locals>.error_handler\u001b[1;34m(*args, **kwargs)\u001b[0m\n\u001b[0;32m     67\u001b[0m     filtered_tb \u001b[38;5;241m=\u001b[39m _process_traceback_frames(e\u001b[38;5;241m.\u001b[39m__traceback__)\n\u001b[0;32m     68\u001b[0m     \u001b[38;5;66;03m# To get the full stack trace, call:\u001b[39;00m\n\u001b[0;32m     69\u001b[0m     \u001b[38;5;66;03m# `tf.debugging.disable_traceback_filtering()`\u001b[39;00m\n\u001b[1;32m---> 70\u001b[0m     \u001b[38;5;28;01mraise\u001b[39;00m e\u001b[38;5;241m.\u001b[39mwith_traceback(filtered_tb) \u001b[38;5;28;01mfrom\u001b[39;00m \u001b[38;5;28;01mNone\u001b[39;00m\n\u001b[0;32m     71\u001b[0m \u001b[38;5;28;01mfinally\u001b[39;00m:\n\u001b[0;32m     72\u001b[0m     \u001b[38;5;28;01mdel\u001b[39;00m filtered_tb\n",
      "File \u001b[1;32m~\\AppData\\Roaming\\Python\\Python311\\site-packages\\tensorflow\\python\\eager\\execute.py:53\u001b[0m, in \u001b[0;36mquick_execute\u001b[1;34m(op_name, num_outputs, inputs, attrs, ctx, name)\u001b[0m\n\u001b[0;32m     51\u001b[0m \u001b[38;5;28;01mtry\u001b[39;00m:\n\u001b[0;32m     52\u001b[0m   ctx\u001b[38;5;241m.\u001b[39mensure_initialized()\n\u001b[1;32m---> 53\u001b[0m   tensors \u001b[38;5;241m=\u001b[39m pywrap_tfe\u001b[38;5;241m.\u001b[39mTFE_Py_Execute(ctx\u001b[38;5;241m.\u001b[39m_handle, device_name, op_name,\n\u001b[0;32m     54\u001b[0m                                       inputs, attrs, num_outputs)\n\u001b[0;32m     55\u001b[0m \u001b[38;5;28;01mexcept\u001b[39;00m core\u001b[38;5;241m.\u001b[39m_NotOkStatusException \u001b[38;5;28;01mas\u001b[39;00m e:\n\u001b[0;32m     56\u001b[0m   \u001b[38;5;28;01mif\u001b[39;00m name \u001b[38;5;129;01mis\u001b[39;00m \u001b[38;5;129;01mnot\u001b[39;00m \u001b[38;5;28;01mNone\u001b[39;00m:\n",
      "\u001b[1;31mInvalidArgumentError\u001b[0m: Graph execution error:\n\nDetected at node sparse_categorical_crossentropy/SparseSoftmaxCrossEntropyWithLogits/SparseSoftmaxCrossEntropyWithLogits defined at (most recent call last):\n  File \"<frozen runpy>\", line 198, in _run_module_as_main\n\n  File \"<frozen runpy>\", line 88, in _run_code\n\n  File \"C:\\ProgramData\\anaconda3\\Lib\\site-packages\\ipykernel_launcher.py\", line 17, in <module>\n\n  File \"C:\\ProgramData\\anaconda3\\Lib\\site-packages\\traitlets\\config\\application.py\", line 992, in launch_instance\n\n  File \"C:\\ProgramData\\anaconda3\\Lib\\site-packages\\ipykernel\\kernelapp.py\", line 736, in start\n\n  File \"C:\\ProgramData\\anaconda3\\Lib\\site-packages\\tornado\\platform\\asyncio.py\", line 195, in start\n\n  File \"C:\\ProgramData\\anaconda3\\Lib\\asyncio\\base_events.py\", line 607, in run_forever\n\n  File \"C:\\ProgramData\\anaconda3\\Lib\\asyncio\\base_events.py\", line 1922, in _run_once\n\n  File \"C:\\ProgramData\\anaconda3\\Lib\\asyncio\\events.py\", line 80, in _run\n\n  File \"C:\\ProgramData\\anaconda3\\Lib\\site-packages\\ipykernel\\kernelbase.py\", line 516, in dispatch_queue\n\n  File \"C:\\ProgramData\\anaconda3\\Lib\\site-packages\\ipykernel\\kernelbase.py\", line 505, in process_one\n\n  File \"C:\\ProgramData\\anaconda3\\Lib\\site-packages\\ipykernel\\kernelbase.py\", line 412, in dispatch_shell\n\n  File \"C:\\ProgramData\\anaconda3\\Lib\\site-packages\\ipykernel\\kernelbase.py\", line 740, in execute_request\n\n  File \"C:\\ProgramData\\anaconda3\\Lib\\site-packages\\ipykernel\\ipkernel.py\", line 422, in do_execute\n\n  File \"C:\\ProgramData\\anaconda3\\Lib\\site-packages\\ipykernel\\zmqshell.py\", line 546, in run_cell\n\n  File \"C:\\ProgramData\\anaconda3\\Lib\\site-packages\\IPython\\core\\interactiveshell.py\", line 3024, in run_cell\n\n  File \"C:\\ProgramData\\anaconda3\\Lib\\site-packages\\IPython\\core\\interactiveshell.py\", line 3079, in _run_cell\n\n  File \"C:\\ProgramData\\anaconda3\\Lib\\site-packages\\IPython\\core\\async_helpers.py\", line 129, in _pseudo_sync_runner\n\n  File \"C:\\ProgramData\\anaconda3\\Lib\\site-packages\\IPython\\core\\interactiveshell.py\", line 3284, in run_cell_async\n\n  File \"C:\\ProgramData\\anaconda3\\Lib\\site-packages\\IPython\\core\\interactiveshell.py\", line 3466, in run_ast_nodes\n\n  File \"C:\\ProgramData\\anaconda3\\Lib\\site-packages\\IPython\\core\\interactiveshell.py\", line 3526, in run_code\n\n  File \"C:\\Users\\alire\\AppData\\Local\\Temp\\ipykernel_22080\\2147496388.py\", line 1, in <module>\n\n  File \"C:\\Users\\alire\\AppData\\Roaming\\Python\\Python311\\site-packages\\keras\\src\\utils\\traceback_utils.py\", line 65, in error_handler\n\n  File \"C:\\Users\\alire\\AppData\\Roaming\\Python\\Python311\\site-packages\\keras\\src\\engine\\training.py\", line 1807, in fit\n\n  File \"C:\\Users\\alire\\AppData\\Roaming\\Python\\Python311\\site-packages\\keras\\src\\engine\\training.py\", line 1401, in train_function\n\n  File \"C:\\Users\\alire\\AppData\\Roaming\\Python\\Python311\\site-packages\\keras\\src\\engine\\training.py\", line 1384, in step_function\n\n  File \"C:\\Users\\alire\\AppData\\Roaming\\Python\\Python311\\site-packages\\keras\\src\\engine\\training.py\", line 1373, in run_step\n\n  File \"C:\\Users\\alire\\AppData\\Roaming\\Python\\Python311\\site-packages\\keras\\src\\engine\\training.py\", line 1151, in train_step\n\n  File \"C:\\Users\\alire\\AppData\\Roaming\\Python\\Python311\\site-packages\\keras\\src\\engine\\training.py\", line 1209, in compute_loss\n\n  File \"C:\\Users\\alire\\AppData\\Roaming\\Python\\Python311\\site-packages\\keras\\src\\engine\\compile_utils.py\", line 277, in __call__\n\n  File \"C:\\Users\\alire\\AppData\\Roaming\\Python\\Python311\\site-packages\\keras\\src\\losses.py\", line 143, in __call__\n\n  File \"C:\\Users\\alire\\AppData\\Roaming\\Python\\Python311\\site-packages\\keras\\src\\losses.py\", line 270, in call\n\n  File \"C:\\Users\\alire\\AppData\\Roaming\\Python\\Python311\\site-packages\\keras\\src\\losses.py\", line 2454, in sparse_categorical_crossentropy\n\n  File \"C:\\Users\\alire\\AppData\\Roaming\\Python\\Python311\\site-packages\\keras\\src\\backend.py\", line 5775, in sparse_categorical_crossentropy\n\nReceived a label value of 3 which is outside the valid range of [0, 2).  Label values: 0 2 3 3 0 0 1 2 1 0 2 2 3 1 1 0 0 2 2 0 0 3 1 2 2 3 1 3 1 2 1 1\n\t [[{{node sparse_categorical_crossentropy/SparseSoftmaxCrossEntropyWithLogits/SparseSoftmaxCrossEntropyWithLogits}}]] [Op:__inference_train_function_3717]"
     ]
    }
   ],
   "source": [
    "model.fit(\n",
    "    train_ds , \n",
    "    epochs=50 , \n",
    "    batch_size=32 , \n",
    "    verbose=1 , \n",
    "    validation_data=val_ds\n",
    "\n",
    "\n",
    "\n",
    ")"
   ]
  },
  {
   "cell_type": "code",
   "execution_count": null,
   "id": "bcd35b25",
   "metadata": {},
   "outputs": [],
   "source": [
    "scores = model.evaluate(test_ds)"
   ]
  },
  {
   "cell_type": "code",
   "execution_count": null,
   "id": "9820154a",
   "metadata": {},
   "outputs": [],
   "source": [
    "def predict(model , img):\n",
    "    img_array = tf.keras.preprocessing.image.img_to_array(images[i].numpy())\n",
    "    img_array = tf.expand_dims(img_array , 0)\n",
    "    \n",
    "    prediction = model.predict(img_array)\n",
    "    predicted_class = class_names[np.argmax(prediction[0])]\n",
    "    \n",
    "    return predicted_class"
   ]
  },
  {
   "cell_type": "code",
   "execution_count": null,
   "id": "e174cfd2",
   "metadata": {},
   "outputs": [],
   "source": [
    "for images , labels in test_ds.take(1):\n",
    "    for i in range(8):\n",
    "        ax = plt.subplot(3 ,3, i + 1)\n",
    "        plt.imshow(images[i].numpy().astype(\"uint8\"))\n",
    "        predicted_class = predict(model , images[i].numpy())\n",
    "        plt.title(f\"pose: {predicted_class}\")\n",
    "        \n",
    "        ax = plt.gca()\n",
    "        ax.get_xaxis().set_visible(False)\n",
    "        ax.get_yaxis().set_visible(False)"
   ]
  },
  {
   "cell_type": "code",
   "execution_count": null,
   "id": "159bf07c",
   "metadata": {},
   "outputs": [],
   "source": [
    "model_version = 2\n",
    "model.save(f\"model/{model_version}\")"
   ]
  }
 ],
 "metadata": {
  "kernelspec": {
   "display_name": "Python 3 (ipykernel)",
   "language": "python",
   "name": "python3"
  },
  "language_info": {
   "codemirror_mode": {
    "name": "ipython",
    "version": 3
   },
   "file_extension": ".py",
   "mimetype": "text/x-python",
   "name": "python",
   "nbconvert_exporter": "python",
   "pygments_lexer": "ipython3",
   "version": "3.11.5"
  }
 },
 "nbformat": 4,
 "nbformat_minor": 5
}
